Workbook
Name Slicer_Business_Unit: #N/A
Name Slicer_Region: #N/A
Name Slicer_Risk_Level: #N/A
Name Slicer_Status: #N/A

Sheet README
A1: Enterprise Data Governance & Compliance Operations Hub
A3: Project objective | B3: Synthetic portfolio project demonstrating governance data maintenance, exception reporting, SharePoint-ready structure, automation design, Power BI-ready metrics, and executive communication.
A4: Reporting snapshot | B4: 46295
A5: Data status | B5: Synthetic / simulated; no employer data.
A6: Workflow | B6: Controls_Raw → Power Query → Cleaned_Controls → SharePoint → Power Automate → Power BI → PowerPoint
A7: Public reference basis | B7: NIST Cybersecurity Framework 2.0 taxonomy; ISO 3166 country standardization; Microsoft implementation documentation.

Sheet PQ_Analysis
A3: Row Labels | B3: Count of Control_ID
A4: Critical | B4: 126
A5: High | B5: 317
A6: Low | B6: 438
A7: Medium | B7: 619
A8: Grand Total | B8: 1500

Sheet PQ_Regional_Analysis
A3: Count of Control_ID | B3: Risk Levels
A4: Regions | B4: Critical | C4: High | D4: Low | E4: Medium | F4: Grand Total
A5: Asia Pacific | B5: 35 | C5: 95 | D5: 149 | E5: 206 | F5: 485
A6: Europe | B6: 46 | C6: 127 | D6: 157 | E6: 207 | F6: 537
A7: North America | B7: 45 | C7: 95 | D7: 132 | E7: 206 | F7: 478
A8: Grand Total | B8: 126 | C8: 317 | D8: 438 | E8: 619 | F8: 1500

Sheet PQ_Issue_Analysis
A1: Row Labels | B1: Sum of Issue_Count
A2: Commercial | B2: 502
A3: Finance | B3: 473
A4: Human Resources | B4: 370
A5: Operations | B5: 450
A6: Risk & Compliance | B6: 436
A7: Technology | B7: 493
A8: Grand Total | B8: 2724

Sheet PQ_Governance_Exceptions
A3: Ownership_Flag | B3: Count of Control_ID | D3: Evidence_Flag | E3: Count of Control_ID | G3: Review_Flag | H3: Count of Control_ID
A4: Assigned | B4: 1468 | D4: Complete | E4: 503 | G4: Current | H4: 622
A5: Missing Owner | B5: 32 | D5: Missing | E5: 503 | G5: Overdue | H5: 878
A6: Grand Total | B6: 1500 | D6: Missing Evidence | E6: 19 | G6: Grand Total | H6: 1500
D7: Pending | E7: 475
D8: Grand Total | E8: 1500

Sheet PQ_Cleaned_Controls
A1: Control_ID | B1: Control_Name | C1: CSF_Function | D1: CSF_Category | E1: Business_Unit | F1: Region | G1: Country | H1: Risk_Level | I1: Control_Owner | J1: Review_Frequency | K1: Last_Review_Date | L1: Next_Review_Date | M1: Status | N1: Evidence_Status | O1: Issue_Count | P1: Remediation_Owner | Q1: Remediation_Due_Date | R1: Remediation_Status | S1: Review_Flag | T1: Ownership_Flag | U1: Evidence_Flag | V1: Risk_Flag
A2: CTRL-0001 | B2: Data Control 1 | C2: GOVERN | D2: GV.RM | E2: Finance | F2: Asia Pacific | G2: Singapore | H2: High | J2: Semiannual | K2: 46150 | L2: 46240 | M2: Overdue | O2: 1 | P2: Alex Chen | Q2: 46167 | R2: Overdue | S2: Overdue | T2: Missing Owner | U2: Missing Evidence | V2: Elevated
A3: CTRL-0002 | B3: Policy Control 2 | C3: PROTECT | D3: PR.AA | E3: Technology | F3: North America | G3: United States | H3: Low | I3: Alex Chen | J3: Quarterly | K3: 45988 | L3: 46078 | M3: Overdue | N3: Missing | O3: 3 | P3: Jordan Lee | Q3: 46227 | R3: Overdue | S3: Overdue | T3: Assigned | U3: Missing | V3: Standard
A4: CTRL-0003 | B4: Reconciliation Control 3 | C4: GOVERN | D4: GV.RM | E4: Operations | F4: Asia Pacific | G4: Singapore | H4: Low | I4: Sam Rivera | J4: Semiannual | K4: 45885 | L4: 46065 | M4: Overdue | N4: Complete | O4: 0 | P4: Taylor Morgan | Q4: 46309 | R4: Not Required | S4: Overdue | T4: Assigned | U4: Complete | V4: Standard
A5: CTRL-0004 | B5: Access Control 4 | C5: GOVERN | D5: GV.RM | E5: Human Resources | F5: North America | G5: Canada | H5: Low | I5: Emma Schmidt | J5: Annual | K5: 46235 | L5: 46600 | M5: Completed | N5: Missing | O5: 2 | P5: Sam Rivera | Q5: 46410 | R5: Completed | S5: Current | T5: Assigned | U5: Missing | V5: Standard
A6: CTRL-0005 | B6: Incident Control 5 | C6: PROTECT | D6: PR.AA | E6: Technology | F6: Europe | G6: United Kingdom | H6: High | I6: Emma Schmidt | J6: Annual | K6: 46133 | L6: 46313 | M6: Not Started | N6: Complete | O6: 2 | P6: Maya Patel | Q6: 46296 | R6: Completed | S6: Current | T6: Assigned | U6: Complete | V6: Elevated
A7: CTRL-0006 | B7: Policy Control 6 | C7: DETECT | D7: DE.CM | E7: Human Resources | F7: Asia Pacific | G7: Singapore | H7: High | I7: Jordan Lee | J7: Quarterly | K7: 46039 | L7: 46219 | M7: Overdue | N7: Pending | O7: 5 | P7: Sam Rivera | Q7: 46400 | R7: Completed | S7: Overdue | T7: Assigned | U7: Pending | V7: Elevated
A8: CTRL-0007 | B8: Incident Control 7 | C8: RESPOND | D8: RS.MA | E8: Risk & Compliance | F8: North America | G8: Canada | H8: Low | I8: Sam Rivera | J8: Semiannual | K8: 45808 | L8: 46173 | M8: Overdue | N8: Missing | O8: 2 | P8: Jordan Lee | Q8: 46223 | R8: Overdue | S8: Overdue | T8: Assigned | U8: Missing | V8: Standard
A9: CTRL-0008 | B9: Data Control 8 | C9: GOVERN | D9: GV.RR | E9: Technology | F9: Europe | G9: United Kingdom | H9: High | I9: Taylor Morgan | J9: Semiannual | K9: 45893 | L9: 46258 | M9: Overdue | N9: Pending | O9: 4 | P9: Maya Patel | Q9: 46319 | R9: In Progress | S9: Overdue | T9: Assigned | U9: Pending | V9: Elevated
A10: CTRL-0009 | B10: Incident Control 9 | C10: GOVERN | D10: GV.OC | E10: Technology | F10: North America | G10: United States | H10: Medium | I10: Emma Schmidt | J10: Annual | K10: 45970 | L10: 46060 | M10: Overdue | N10: Pending | O10: 3 | P10: Maya Patel | Q10: 46354 | R10: In Progress | S10: Overdue | T10: Assigned | U10: Pending | V10: Standard
A11: CTRL-0010 | B11: Data Control 10 | C11: GOVERN | D11: GV.RR | E11: Commercial | F11: Asia Pacific | G11: Singapore | H11: Medium | I11: Taylor Morgan | J11: Quarterly | K11: 46053 | L11: 46143 | M11: Overdue | N11: Pending | O11: 0 | P11: Taylor Morgan | Q11: 46249 | R11: Not Required | S11: Overdue | T11: Assigned | U11: Pending | V11: Standard
A12: CTRL-0011 | B12: Policy Control 11 | C12: DETECT | D12: DE.CM | E12: Technology | F12: Asia Pacific | G12: Singapore | H12: Medium | I12: Jordan Lee | J12: Semiannual | K12: 45999 | L12: 46364 | M12: Not Started | N12: Pending | O12: 0 | P12: Sam Rivera | Q12: 46172 | R12: Not Required | S12: Current | T12: Assigned | U12: Pending | V12: Standard
A13: CTRL-0012 | B13: Data Control 12 | C13: RECOVER | D13: RC.RP | E13: Human Resources | F13: North America | G13: United States | H13: Critical | I13: Maya Patel | J13: Quarterly | K13: 45901 | L13: 46081 | M13: Overdue | N13: Complete | O13: 4 | P13: Taylor Morgan | Q13: 46179 | R13: Completed | S13: Overdue | T13: Assigned | U13: Complete | V13: Elevated
A14: CTRL-0013 | B14: Access Control 13 | C14: RECOVER | D14: RC.RP | E14: Technology | F14: Asia Pacific | G14: Singapore | H14: Critical | I14: Sam Rivera | J14: Quarterly | K14: 45910 | L14: 46090 | M14: Overdue | N14: Pending | O14: 5 | P14: Sam Rivera | Q14: 46306 | R14: In Progress | S14: Overdue | T14: Assigned | U14: Pending | V14: Elevated
... A48: CTRL-0012 | B48: Data Control 47 | C48: PROTECT | D48: PR.AA | E48: Operations | F48: Europe | G48: Germany | H48: Low | I48: Noah Williams | J48: Quarterly | K48: 46182 | L48: 46362 | M48: Completed | N48: Pending | O48: 2 | P48: Sam Rivera | Q48: 46258 | R48: Overdue | S48: Current | T48: Assigned | U48: Pending | V48: Standard
A49: CTRL-0013 | B49: Access Control 48 | C49: GOVERN | D49: GV.OC | E49: Commercial | F49: North America | G49: United States | H49: Medium | J49: Semiannual | K49: 45991 | L49: 46081 | M49: Overdue | N49: Missing | O49: 3 | P49: Sam Rivera | Q49: 46366 | R49: In Progress | S49: Overdue | T49: Missing Owner | U49: Missing | V49: Standard
A50: CTRL-0014 | B50: Reconciliation Control 49 | C50: PROTECT | D50: PR.AA | E50: Operations | F50: Europe | G50: United Kingdom | H50: Medium | I50: Noah Williams | J50: Semiannual | K50: 46033 | L50: 46398 | M50: Completed | N50: Pending | O50: 2 | P50: Sam Rivera | Q50: 46295 | R50: In Progress | S50: Current | T50: Assigned | U50: Pending | V50: Standard
A51: CTRL-0015 | B51: Access Control 50 | C51: PROTECT | D51: PR.AA | E51: Operations | F51: North America | G51: United States | H51: Low | I51: Jordan Lee | J51: Quarterly | K51: 46177 | L51: 46267 | M51: Overdue | N51: Missing | O51: 3 | P51: Taylor Morgan | Q51: 46256 | R51: Overdue | S51: Overdue | T51: Assigned | U51: Missing | V51: Standard
A52: CTRL-0016 | B52: Access Control 51 | C52: RECOVER | D52: RC.RP | E52: Technology | F52: North America | G52: Canada | H52: Medium | I52: Jordan Lee | J52: Quarterly | K52: 46135 | L52: 46225 | M52: Overdue | N52: Complete | O52: 2 | P52: Taylor Morgan | Q52: 46179 | R52: Overdue | S52: Overdue | T52: Assigned | U52: Complete | V52: Standard
A53: CTRL-0017 | B53: Change Control 52 | C53: GOVERN | D53: GV.OC | E53: Risk & Compliance | F53: Europe | G53: Germany | H53: Medium | I53: Alex Chen | J53: Quarterly | K53: 46146 | L53: 46326 | M53: Completed | N53: Complete | O53: 3 | P53: Taylor Morgan | Q53: 46366 | R53: Completed | S53: Current | T53: Assigned | U53: Complete | V53: Standard
A54: CTRL-0018 | B54: Policy Control 53 | C54: PROTECT | D54: PR.AA | E54: Finance | F54: North America | G54: United States | H54: Medium | I54: Emma Schmidt | J54: Annual | K54: 45965 | L54: 46330 | M54: In Progress | N54: Missing | O54: 3 | P54: Emma Schmidt | Q54: 46345 | R54: In Progress | S54: Current | T54: Assigned | U54: Missing | V54: Standard
A55: CTRL-0019 | B55: Change Control 54 | C55: GOVERN | D55: GV.RR | E55: Human Resources | F55: Europe | G55: United Kingdom | H55: Critical | I55: Maya Patel | J55: Quarterly | K55: 45885 | L55: 45975 | M55: Overdue | N55: Missing | O55: 1 | P55: Maya Patel | Q55: 46250 | R55: Overdue | S55: Overdue | T55: Assigned | U55: Missing | V55: Elevated
A56: CTRL-0020 | B56: Access Control 55 | C56: RECOVER | D56: RC.RP | E56: Risk & Compliance | F56: North America | G56: United States | H56: Medium | I56: Liam Brown | J56: Annual | K56: 46126 | L56: 46216 | M56: Overdue | N56: Complete | O56: 2 | P56: Sam Rivera | Q56: 46259 | R56: Overdue | S56: Overdue | T56: Assigned | U56: Complete | V56: Standard
A57: CTRL-0056 | B57: Data Control 56 | C57: PROTECT | D57: PR.AA | E57: Risk & Compliance | F57: Europe | G57: United Kingdom | H57: Low | I57: Sam Rivera | J57: Annual | K57: 45944 | L57: 46034 | M57: Overdue | N57: Pending | O57: 1 | P57: Taylor Morgan | Q57: 46151 | R57: Completed | S57: Overdue | T57: Assigned | U57: Pending | V57: Standard
A58: CTRL-0057 | B58: Incident Control 57 | C58: RESPOND | D58: RS.MA | E58: Risk & Compliance | F58: Europe | G58: United Kingdom | H58: Medium | I58: Emma Schmidt | J58: Semiannual | K58: 46136 | L58: 46501 | M58: Completed | N58: Pending | O58: 0 | P58: Taylor Morgan | Q58: 46135 | R58: Not Required | S58: Current | T58: Assigned | U58: Pending | V58: Standard
A59: CTRL-0058 | B59: Vendor Control 58 | C59: GOVERN | D59: GV.RR | E59: Technology | F59: North America | G59: United States | H59: Critical | I59: Alex Chen | J59: Annual | K59: 45884 | L59: 46249 | M59: Overdue | N59: Pending | O59: 4 | P59: Liam Brown | Q59: 46135 | R59: Overdue | S59: Overdue | T59: Assigned | U59: Pending | V59: Elevated
A60: CTRL-0059 | B60: Vendor Control 59 | C60: DETECT | D60: DE.CM | E60: Human Resources | F60: Europe | G60: United Kingdom | H60: Medium | I60: Liam Brown | J60: Annual | K60: 46229 | L60: 46409 | M60: Completed | N60: Pending | O60: 2 | P60: Liam Brown | Q60: 46168 | R60: Overdue | S60: Current | T60: Assigned | U60: Pending | V60: Standard
A61: CTRL-0060 | B61: Incident Control 60 | C61: GOVERN | D61: GV.OC | E61: Human Resources | F61: Europe | G61: Germany | H61: Low | I61: Maya Patel | J61: Annual | K61: 46114 | L61: 46294 | M61: Overdue | N61: Pending | O61: 0 | P61: Liam Brown | Q61: 46321 | R61: Not Required | S61: Overdue | T61: Assigned | U61: Pending | V61: Standard
... A84: CTRL-0083 | B84: Change Control 83 | C84: GOVERN | D84: GV.OC | E84: Technology | F84: Asia Pacific | G84: Singapore | H84: Low | I84: Alex Chen | J84: Annual | K84: 46208 | L84: 46298 | M84: Completed | N84: Complete | O84: 2 | P84: Emma Schmidt | Q84: 46123 | R84: Completed | S84: Current | T84: Assigned | U84: Complete | V84: Standard
A85: CTRL-0084 | B85: Data Control 84 | C85: IDENTIFY | D85: ID.AM | E85: Commercial | F85: Asia Pacific | G85: Singapore | H85: Low | I85: Liam Brown | J85: Quarterly | K85: 45877 | L85: 46057 | M85: Overdue | O85: 0 | P85: Taylor Morgan | Q85: 46346 | R85: Not Required | S85: Overdue | T85: Assigned | U85: Missing Evidence | V85: Standard
A86: CTRL-0085 | B86: Data Control 85 | C86: DETECT | D86: DE.CM | E86: Finance | F86: Europe | G86: United Kingdom | H86: Critical | I86: Emma Schmidt | J86: Quarterly | K86: 46057 | L86: 46422 | M86: Completed | N86: Missing | O86: 3 | P86: Maya Patel | Q86: 46152 | R86: Overdue | S86: Current | T86: Assigned | U86: Missing | V86: Elevated
A87: CTRL-0086 | B87: Policy Control 86 | C87: GOVERN | D87: GV.RM | E87: Human Resources | F87: North America | G87: Canada | H87: Medium | I87: Noah Williams | J87: Annual | K87: 46080 | L87: 46445 | M87: Completed | N87: Pending | O87: 3 | P87: Sam Rivera | Q87: 46165 | R87: Overdue | S87: Current | T87: Assigned | U87: Pending | V87: Standard
A88: CTRL-0087 | B88: Reconciliation Control 87 | C88: RESPOND | D88: RS.MA | E88: Technology | F88: Europe | G88: Germany | H88: Medium | I88: Liam Brown | J88: Annual | K88: 46071 | L88: 46251 | M88: Overdue | N88: Missing | O88: 0 | P88: Taylor Morgan | Q88: 46275 | R88: Not Required | S88: Overdue | T88: Assigned | U88: Missing | V88: Standard
A89: CTRL-0088 | B89: Data Control 88 | C89: GOVERN | D89: GV.OC | E89: Commercial | F89: Europe | G89: United Kingdom | H89: Critical | I89: Maya Patel | J89: Annual | K89: 46229 | L89: 46319 | M89: Completed | N89: Complete | O89: 5 | P89: Noah Williams | Q89: 46305 | R89: In Progress | S89: Current | T89: Assigned | U89: Complete | V89: Elevated
A90: CTRL-0089 | B90: Change Control 89 | C90: IDENTIFY | D90: ID.AM | E90: Risk & Compliance | F90: Asia Pacific | G90: Singapore | H90: Medium | I90: Emma Schmidt | J90: Annual | K90: 45831 | L90: 46196 | M90: Overdue | N90: Complete | O90: 2 | P90: Liam Brown | Q90: 46274 | R90: Overdue | S90: Overdue | T90: Assigned | U90: Complete | V90: Standard
A91: CTRL-0090 | B91: Access Control 90 | C91: PROTECT | D91: PR.AA | E91: Operations | F91: North America | G91: United States | H91: High | I91: Noah Williams | J91: Quarterly | K91: 46217 | L91: 46397 | M91: Not Started | N91: Missing | O91: 4 | P91: Taylor Morgan | Q91: 46400 | R91: Completed | S91: Current | T91: Assigned | U91: Missing | V91: Elevated
A92: CTRL-0091 | B92: Access Control 91 | C92: GOVERN | D92: GV.OC | E92: Operations | F92: Asia Pacific | G92: Singapore | H92: Medium | I92: Jordan Lee | J92: Annual | K92: 45830 | L92: 45920 | M92: Overdue | N92: Missing | O92: 3 | P92: Sam Rivera | Q92: 46150 | R92: Completed | S92: Overdue | T92: Assigned | U92: Missing | V92: Standard
A93: CTRL-0092 | B93: Change Control 92 | C93: GOVERN | D93: GV.RR | E93: Risk & Compliance | F93: Europe | G93: Germany | H93: Medium | I93: Noah Williams | J93: Annual | K93: 46116 | L93: 46481 | M93: Completed | N93: Missing | O93: 0 | P93: Alex Chen | Q93: 46141 | R93: Not Required | S93: Current | T93: Assigned | U93: Missing | V93: Standard
A94: CTRL-0093 | B94: Access Control 93 | C94: RESPOND | D94: RS.MA | E94: Operations | F94: Asia Pacific | G94: Singapore | H94: Medium | I94: Emma Schmidt | J94: Semiannual | K94: 46027 | L94: 46392 | M94: Completed | N94: Pending | O94: 1 | P94: Liam Brown | Q94: 46377 | R94: Completed | S94: Current | T94: Assigned | U94: Pending | V94: Standard
A95: CTRL-0094 | B95: Access Control 94 | C95: GOVERN | D95: GV.RM | E95: Finance | F95: Asia Pacific | G95: Singapore | H95: Low | I95: Alex Chen | J95: Semiannual | K95: 46272 | L95: 46362 | M95: Completed | N95: Complete | O95: 1 | P95: Emma Schmidt | Q95: 46245 | R95: Completed | S95: Current | T95: Assigned | U95: Complete | V95: Standard
...

Sheet Final_Dashboard
A1: ENTERPRISE DATA GOVERNANCE & COMPLIANCE
A2: Management Control Monitoring Dashboard
A3: Synthetic Portfolio Case Study | Reporting Snapshot: 30 September 2026

Sheet Controls_Raw
A1: Controls Raw
A4: Control_ID | B4: Control_Name | C4: CSF_Function | D4: CSF_Category | E4: Business_Unit | F4: Region | G4: Country | H4: Risk_Level | I4: Control_Owner | J4: Review_Frequency | K4: Last_Review_Date | L4: Next_Review_Date | M4: Status | N4: Evidence_Status | O4: Issue_Count | P4: Remediation_Owner | Q4: Remediation_Due_Date | R4: Remediation_Status
A5: CTRL-0001 | B5: Data Control 1 | C5: GOVERN | D5: GV.RM | E5: Finance | F5: Asia Pacific | G5: Singapore | H5: High | J5: Semiannual | K5: 46150 | L5: 46240 | M5: Overdue | O5: 1 | P5: Alex Chen | Q5: 46167 | R5: Overdue
A6: CTRL-0002 | B6: Policy Control 2 | C6: PROTECT | D6: PR.AA | E6: Technology | F6: North America | G6: United States | H6: Low | I6: Alex Chen | J6: Quarterly | K6: 45988 | L6: 46078 | M6: Overdue | N6: Missing | O6: 3 | P6: Jordan Lee | Q6: 46227 | R6: Overdue
A7: CTRL-0003 | B7: Reconciliation Control 3 | C7: GOVERN | D7: GV.RM | E7: Operations | F7: Asia Pacific | G7: Singapore | H7: Low | I7: Sam Rivera | J7: Semiannual | K7: 45885 | L7: 46065 | M7: Overdue | N7: Complete | O7: 0 | P7: Taylor Morgan | Q7: 46309 | R7: Not Required
A8: CTRL-0004 | B8: Access Control 4 | C8: GOVERN | D8: GV.RM | E8: Human Resources | F8: North America | G8: Canada | H8: Low | I8: Emma Schmidt | J8: Annual | K8: 46235 | L8: 46600 | M8: Completed | N8: Missing | O8: 2 | P8: Sam Rivera | Q8: 46410 | R8: Completed
A9: CTRL-0005 | B9: Incident Control 5 | C9: PROTECT | D9: PR.AA | E9: Technology | F9: Europe | G9: United Kingdom | H9: High | I9: Emma Schmidt | J9: Annual | K9: 46133 | L9: 46313 | M9: Not Started | N9: Complete | O9: 2 | P9: Maya Patel | Q9: 46296 | R9: Completed
A10: CTRL-0006 | B10: Policy Control 6 | C10: DETECT | D10: DE.CM | E10: Human Resources | F10: Asia Pacific | G10: Singapore | H10: High | I10: Jordan Lee | J10: Quarterly | K10: 46039 | L10: 46219 | M10: Overdue | N10: Pending | O10: 5 | P10: Sam Rivera | Q10: 46400 | R10: Completed
A11: CTRL-0007 | B11: Incident Control 7 | C11: RESPOND | D11: RS.MA | E11: Risk & Compliance | F11: North America | G11: Canada | H11: Low | I11: Sam Rivera | J11: Semiannual | K11: 45808 | L11: 46173 | M11: Overdue | N11: Missing | O11: 2 | P11: Jordan Lee | Q11: 46223 | R11: Overdue
A12: CTRL-0008 | B12: Data Control 8 | C12: GOVERN | D12: GV.RR | E12: Technology | F12: Europe | G12: United Kingdom | H12: High | I12: Taylor Morgan | J12: Semiannual | K12: 45893 | L12: 46258 | M12: Overdue | N12: Pending | O12: 4 | P12: Maya Patel | Q12: 46319 | R12: In Progress
A13: CTRL-0009 | B13: Incident Control 9 | C13: GOVERN | D13: GV.OC | E13: Technology | F13: North America | G13: United States | H13: Medium | I13: Emma Schmidt | J13: Annual | K13: 45970 | L13: 46060 | M13: Overdue | N13: Pending | O13: 3 | P13: Maya Patel | Q13: 46354 | R13: In Progress
A14: CTRL-0010 | B14: Data Control 10 | C14: GOVERN | D14: GV.RR | E14: Commercial | F14: Asia Pacific | G14: Singapore | H14: Medium | I14: Taylor Morgan | J14: Quarterly | K14: 46053 | L14: 46143 | M14: Overdue | N14: Pending | O14: 0 | P14: Taylor Morgan | Q14: 46249 | R14: Not Required
A15: CTRL-0011 | B15: Policy Control 11 | C15: DETECT | D15: DE.CM | E15: Technology | F15: Asia Pacific | G15: Singapore | H15: Medium | I15: Jordan Lee | J15: Semiannual | K15: 45999 | L15: 46364 | M15: Not Started | N15: Pending | O15: 0 | P15: Sam Rivera | Q15: 46172 | R15: Not Required
A16: CTRL-0012 | B16: Data Control 12 | C16: RECOVER | D16: RC.RP | E16: Human Resources | F16: North America | G16: United States | H16: Critical | I16: Maya Patel | J16: Quarterly | K16: 45901 | L16: 46081 | M16: Overdue | N16: Complete | O16: 4 | P16: Taylor Morgan | Q16: 46179 | R16: Completed
A17: CTRL-0013 | B17: Access Control 13 | C17: RECOVER | D17: RC.RP | E17: Technology | F17: Asia Pacific | G17: Singapore | H17: Critical | I17: Sam Rivera | J17: Quarterly | K17: 45910 | L17: 46090 | M17: Overdue | N17: Pending | O17: 5 | P17: Sam Rivera | Q17: 46306 | R17: In Progress
... A51: CTRL-0012 | B51: Data Control 47 | C51: PROTECT | D51: PR.AA | E51: Operations | F51: Europe | G51: Germany | H51: Low | I51: Noah Williams | J51: Quarterly | K51: 46182 | L51: 46362 | M51: Completed | N51: Pending | O51: 2 | P51: Sam Rivera | Q51: 46258 | R51: Overdue
A52: CTRL-0013 | B52: Access Control 48 | C52: GOVERN | D52: GV.OC | E52: Commercial | F52: North America | G52: United States | H52: Medium | J52: Semiannual | K52: 45991 | L52: 46081 | M52: Overdue | N52: Missing | O52: 3 | P52: Sam Rivera | Q52: 46366 | R52: In Progress
A53: CTRL-0014 | B53: Reconciliation Control 49 | C53: PROTECT | D53: PR.AA | E53: Operations | F53: Europe | G53: United Kingdom | H53: Medium | I53: Noah Williams | J53: Semiannual | K53: 46033 | L53: 46398 | M53: Completed | N53: Pending | O53: 2 | P53: Sam Rivera | Q53: 46295 | R53: In Progress
A54: CTRL-0015 | B54: Access Control 50 | C54: PROTECT | D54: PR.AA | E54: Operations | F54: North America | G54: United States | H54: Low | I54: Jordan Lee | J54: Quarterly | K54: 46177 | L54: 46267 | M54: Overdue | N54: Missing | O54: 3 | P54: Taylor Morgan | Q54: 46256 | R54: Overdue
A55: CTRL-0016 | B55: Access Control 51 | C55: RECOVER | D55: RC.RP | E55: Technology | F55: North America | G55: Canada | H55: Medium | I55: Jordan Lee | J55: Quarterly | K55: 46135 | L55: 46225 | M55: Overdue | N55: Complete | O55: 2 | P55: Taylor Morgan | Q55: 46179 | R55: Overdue
A56: CTRL-0017 | B56: Change Control 52 | C56: GOVERN | D56: GV.OC | E56: Risk & Compliance | F56: Europe | G56: Germany | H56: Medium | I56: Alex Chen | J56: Quarterly | K56: 46146 | L56: 46326 | M56: Completed | N56: Complete | O56: 3 | P56: Taylor Morgan | Q56: 46366 | R56: Completed
A57: CTRL-0018 | B57: Policy Control 53 | C57: PROTECT | D57: PR.AA | E57: Finance | F57: North America | G57: United States | H57: Medium | I57: Emma Schmidt | J57: Annual | K57: 45965 | L57: 46330 | M57: In Progress | N57: Missing | O57: 3 | P57: Emma Schmidt | Q57: 46345 | R57: In Progress
A58: CTRL-0019 | B58: Change Control 54 | C58: GOVERN | D58: GV.RR | E58: Human Resources | F58: Europe | G58: UK | H58: Critical | I58: Maya Patel | J58: Quarterly | K58: 45885 | L58: 45975 | M58: Overdue | N58: Missing | O58: 1 | P58: Maya Patel | Q58: 46250 | R58: Overdue
A59: CTRL-0020 | B59: Access Control 55 | C59: RECOVER | D59: RC.RP | E59: Risk & Compliance | F59: North America | G59: United States | H59: Medium | I59: Liam Brown | J59: Annual | K59: 46126 | L59: 46216 | M59: Overdue | N59: Complete | O59: 2 | P59: Sam Rivera | Q59: 46259 | R59: Overdue
A60: CTRL-0056 | B60: Data Control 56 | C60: PROTECT | D60: PR.AA | E60: Risk & Compliance | F60: Europe | G60: United Kingdom | H60: Low | I60: Sam Rivera | J60: Annual | K60: 45944 | L60: 46034 | M60: Overdue | N60: Pending | O60: 1 | P60: Taylor Morgan | Q60: 46151 | R60: Completed
A61: CTRL-0057 | B61: Incident Control 57 | C61: RESPOND | D61: RS.MA | E61: Risk & Compliance | F61: Europe | G61: United Kingdom | H61: Medium | I61: Emma Schmidt | J61: Semiannual | K61: 46136 | L61: 46501 | M61: Completed | N61: Pending | O61: 0 | P61: Taylor Morgan | Q61: 46135 | R61: Not Required
A62: CTRL-0058 | B62: Vendor Control 58 | C62: GOVERN | D62: GV.RR | E62: Technology | F62: North America | G62: United States | H62: Critical | I62: Alex Chen | J62: Annual | K62: 45884 | L62: 46249 | M62: Overdue | N62: Pending | O62: 4 | P62: Liam Brown | Q62: 46135 | R62: Overdue
A63: CTRL-0059 | B63: Vendor Control 59 | C63: DETECT | D63: DE.CM | E63: Human Resources | F63: Europe | G63: United Kingdom | H63: Medium | I63: Liam Brown | J63: Annual | K63: 46229 | L63: 46409 | M63: Completed | N63: Pending | O63: 2 | P63: Liam Brown | Q63: 46168 | R63: Overdue
A64: CTRL-0060 | B64: Incident Control 60 | C64: GOVERN | D64: GV.OC | E64: Human Resources | F64: Europe | G64: Germany | H64: Low | I64: Maya Patel | J64: Annual | K64: 46114 | L64: 46294 | M64: Overdue | N64: Pending | O64: 0 | P64: Liam Brown | Q64: 46321 | R64: Not Required
... A87: CTRL-0083 | B87: Change Control 83 | C87: GOVERN | D87: GV.OC | E87: Technology | F87: Asia Pacific | G87: Singapore | H87: Low | I87: Alex Chen | J87: Annual | K87: 46208 | L87: 46298 | M87: Completed | N87: Complete | O87: 2 | P87: Emma Schmidt | Q87: 46123 | R87: Completed
A88: CTRL-0084 | B88: Data Control 84 | C88: IDENTIFY | D88: ID.AM | E88: Commercial | F88: Asia Pacific | G88: Singapore | H88: Low | I88: Liam Brown | J88: Quarterly | K88: 45877 | L88: 46057 | M88: Overdue | O88: 0 | P88: Taylor Morgan | Q88: 46346 | R88: Not Required
A89: CTRL-0085 | B89: Data Control 85 | C89: DETECT | D89: DE.CM | E89: Finance | F89: Europe | G89: United Kingdom | H89: Critical | I89: Emma Schmidt | J89: Quarterly | K89: 46057 | L89: 46422 | M89: Completed | N89: Missing | O89: 3 | P89: Maya Patel | Q89: 46152 | R89: Overdue
A90: CTRL-0086 | B90: Policy Control 86 | C90: GOVERN | D90: GV.RM | E90: Human Resources | F90: North America | G90: Canada | H90: Medium | I90: Noah Williams | J90: Annual | K90: 46080 | L90: 46445 | M90: Completed | N90: Pending | O90: 3 | P90: Sam Rivera | Q90: 46165 | R90: Overdue
A91: CTRL-0087 | B91: Reconciliation Control 87 | C91: RESPOND | D91: RS.MA | E91: Technology | F91: Europe | G91: Germany | H91: Medium | I91: Liam Brown | J91: Annual | K91: 46071 | L91: 46251 | M91: Overdue | N91: Missing | O91: 0 | P91: Taylor Morgan | Q91: 46275 | R91: Not Required
A92: CTRL-0088 | B92: Data Control 88 | C92: GOVERN | D92: GV.OC | E92: Commercial | F92: Europe | G92: United Kingdom | H92: Critical | I92: Maya Patel | J92: Annual | K92: 46229 | L92: 46319 | M92: Completed | N92: Complete | O92: 5 | P92: Noah Williams | Q92: 46305 | R92: In Progress
A93: CTRL-0089 | B93: Change Control 89 | C93: IDENTIFY | D93: ID.AM | E93: Risk & Compliance | F93: Asia Pacific | G93: Singapore | H93: Medium | I93: Emma Schmidt | J93: Annual | K93: 45831 | L93: 46196 | M93: Overdue | N93: Complete | O93: 2 | P93: Liam Brown | Q93: 46274 | R93: Overdue
A94: CTRL-0090 | B94: Access Control 90 | C94: PROTECT | D94: PR.AA | E94: Operations | F94: North America | G94: United States | H94: High | I94: Noah Williams | J94: Quarterly | K94: 46217 | L94: 46397 | M94: Not Started | N94: Missing | O94: 4 | P94: Taylor Morgan | Q94: 46400 | R94: Completed
A95: CTRL-0091 | B95: Access Control 91 | C95: GOVERN | D95: GV.OC | E95: Operations | F95: Asia Pacific | G95: Singapore | H95: Medium | I95: Jordan Lee | J95: Annual | K95: 45830 | L95: 45920 | M95: Overdue | N95: Missing | O95: 3 | P95: Sam Rivera | Q95: 46150 | R95: Completed
A96: CTRL-0092 | B96: Change Control 92 | C96: GOVERN | D96: GV.RR | E96: Risk & Compliance | F96: Europe | G96: Germany | H96: Medium | I96: Noah Williams | J96: Annual | K96: 46116 | L96: 46481 | M96: Completed | N96: Missing | O96: 0 | P96: Alex Chen | Q96: 46141 | R96: Not Required
A97: CTRL-0093 | B97: Access Control 93 | C97: RESPOND | D97: RS.MA | E97: Operations | F97: Asia Pacific | G97: Singapore | H97: Medium | I97: Emma Schmidt | J97: Semiannual | K97: 46027 | L97: 46392 | M97: Completed | N97: Pending | O97: 1 | P97: Liam Brown | Q97: 46377 | R97: Completed
...

Sheet Cleaned_Controls
A1: Cleaned Controls
A4: Control_ID | B4: Control_Name | C4: CSF_Function | D4: CSF_Category | E4: Business_Unit | F4: Region | G4: Country | H4: Risk_Level | I4: Control_Owner | J4: Review_Frequency | K4: Last_Review_Date | L4: Next_Review_Date | M4: Status | N4: Evidence_Status | O4: Issue_Count | P4: Remediation_Owner | Q4: Remediation_Due_Date | R4: Remediation_Status
A5: CTRL-0001 | B5: Data Control 1 | C5: GOVERN | D5: GV.RM | E5: Finance | F5: Asia Pacific | G5: Singapore | H5: High | J5: Semiannual | K5: 46150 | L5: 46240 | M5: Overdue | O5: 1 | P5: Alex Chen | Q5: 46167 | R5: Overdue
A6: CTRL-0002 | B6: Policy Control 2 | C6: PROTECT | D6: PR.AA | E6: Technology | F6: North America | G6: United States | H6: Low | I6: Alex Chen | J6: Quarterly | K6: 45988 | L6: 46078 | M6: Overdue | N6: Missing | O6: 3 | P6: Jordan Lee | Q6: 46227 | R6: Overdue
A7: CTRL-0003 | B7: Reconciliation Control 3 | C7: GOVERN | D7: GV.RM | E7: Operations | F7: Asia Pacific | G7: Singapore | H7: Low | I7: Sam Rivera | J7: Semiannual | K7: 45885 | L7: 46065 | M7: Overdue | N7: Complete | O7: 0 | P7: Taylor Morgan | Q7: 46309 | R7: Not Required
A8: CTRL-0004 | B8: Access Control 4 | C8: GOVERN | D8: GV.RM | E8: Human Resources | F8: North America | G8: Canada | H8: Low | I8: Emma Schmidt | J8: Annual | K8: 46235 | L8: 46600 | M8: Completed | N8: Missing | O8: 2 | P8: Sam Rivera | Q8: 46410 | R8: Completed
A9: CTRL-0005 | B9: Incident Control 5 | C9: PROTECT | D9: PR.AA | E9: Technology | F9: Europe | G9: United Kingdom | H9: High | I9: Emma Schmidt | J9: Annual | K9: 46133 | L9: 46313 | M9: Not Started | N9: Complete | O9: 2 | P9: Maya Patel | Q9: 46296 | R9: Completed
A10: CTRL-0006 | B10: Policy Control 6 | C10: DETECT | D10: DE.CM | E10: Human Resources | F10: Asia Pacific | G10: Singapore | H10: High | I10: Jordan Lee | J10: Quarterly | K10: 46039 | L10: 46219 | M10: Overdue | N10: Pending | O10: 5 | P10: Sam Rivera | Q10: 46400 | R10: Completed
A11: CTRL-0007 | B11: Incident Control 7 | C11: RESPOND | D11: RS.MA | E11: Risk & Compliance | F11: North America | G11: Canada | H11: Low | I11: Sam Rivera | J11: Semiannual | K11: 45808 | L11: 46173 | M11: Overdue | N11: Missing | O11: 2 | P11: Jordan Lee | Q11: 46223 | R11: Overdue
A12: CTRL-0008 | B12: Data Control 8 | C12: GOVERN | D12: GV.RR | E12: Technology | F12: Europe | G12: United Kingdom | H12: High | I12: Taylor Morgan | J12: Semiannual | K12: 45893 | L12: 46258 | M12: Overdue | N12: Pending | O12: 4 | P12: Maya Patel | Q12: 46319 | R12: In Progress
A13: CTRL-0009 | B13: Incident Control 9 | C13: GOVERN | D13: GV.OC | E13: Technology | F13: North America | G13: United States | H13: Medium | I13: Emma Schmidt | J13: Annual | K13: 45970 | L13: 46060 | M13: Overdue | N13: Pending | O13: 3 | P13: Maya Patel | Q13: 46354 | R13: In Progress
A14: CTRL-0010 | B14: Data Control 10 | C14: GOVERN | D14: GV.RR | E14: Commercial | F14: Asia Pacific | G14: Singapore | H14: Medium | I14: Taylor Morgan | J14: Quarterly | K14: 46053 | L14: 46143 | M14: Overdue | N14: Pending | O14: 0 | P14: Taylor Morgan | Q14: 46249 | R14: Not Required
A15: CTRL-0011 | B15: Policy Control 11 | C15: DETECT | D15: DE.CM | E15: Technology | F15: Asia Pacific | G15: Singapore | H15: Medium | I15: Jordan Lee | J15: Semiannual | K15: 45999 | L15: 46364 | M15: Not Started | N15: Pending | O15: 0 | P15: Sam Rivera | Q15: 46172 | R15: Not Required
A16: CTRL-0012 | B16: Data Control 12 | C16: RECOVER | D16: RC.RP | E16: Human Resources | F16: North America | G16: United States | H16: Critical | I16: Maya Patel | J16: Quarterly | K16: 45901 | L16: 46081 | M16: Overdue | N16: Complete | O16: 4 | P16: Taylor Morgan | Q16: 46179 | R16: Completed
A17: CTRL-0013 | B17: Access Control 13 | C17: RECOVER | D17: RC.RP | E17: Technology | F17: Asia Pacific | G17: Singapore | H17: Critical | I17: Sam Rivera | J17: Quarterly | K17: 45910 | L17: 46090 | M17: Overdue | N17: Pending | O17: 5 | P17: Sam Rivera | Q17: 46306 | R17: In Progress
... A51: CTRL-0012 | B51: Data Control 47 | C51: PROTECT | D51: PR.AA | E51: Operations | F51: Europe | G51: Germany | H51: Low | I51: Noah Williams | J51: Quarterly | K51: 46182 | L51: 46362 | M51: Completed | N51: Pending | O51: 2 | P51: Sam Rivera | Q51: 46258 | R51: Overdue
A52: CTRL-0013 | B52: Access Control 48 | C52: GOVERN | D52: GV.OC | E52: Commercial | F52: North America | G52: United States | H52: Medium | J52: Semiannual | K52: 45991 | L52: 46081 | M52: Overdue | N52: Missing | O52: 3 | P52: Sam Rivera | Q52: 46366 | R52: In Progress
A53: CTRL-0014 | B53: Reconciliation Control 49 | C53: PROTECT | D53: PR.AA | E53: Operations | F53: Europe | G53: United Kingdom | H53: Medium | I53: Noah Williams | J53: Semiannual | K53: 46033 | L53: 46398 | M53: Completed | N53: Pending | O53: 2 | P53: Sam Rivera | Q53: 46295 | R53: In Progress
A54: CTRL-0015 | B54: Access Control 50 | C54: PROTECT | D54: PR.AA | E54: Operations | F54: North America | G54: United States | H54: Low | I54: Jordan Lee | J54: Quarterly | K54: 46177 | L54: 46267 | M54: Overdue | N54: Missing | O54: 3 | P54: Taylor Morgan | Q54: 46256 | R54: Overdue
A55: CTRL-0016 | B55: Access Control 51 | C55: RECOVER | D55: RC.RP | E55: Technology | F55: North America | G55: Canada | H55: Medium | I55: Jordan Lee | J55: Quarterly | K55: 46135 | L55: 46225 | M55: Overdue | N55: Complete | O55: 2 | P55: Taylor Morgan | Q55: 46179 | R55: Overdue
A56: CTRL-0017 | B56: Change Control 52 | C56: GOVERN | D56: GV.OC | E56: Risk & Compliance | F56: Europe | G56: Germany | H56: Medium | I56: Alex Chen | J56: Quarterly | K56: 46146 | L56: 46326 | M56: Completed | N56: Complete | O56: 3 | P56: Taylor Morgan | Q56: 46366 | R56: Completed
A57: CTRL-0018 | B57: Policy Control 53 | C57: PROTECT | D57: PR.AA | E57: Finance | F57: North America | G57: United States | H57: Medium | I57: Emma Schmidt | J57: Annual | K57: 45965 | L57: 46330 | M57: In Progress | N57: Missing | O57: 3 | P57: Emma Schmidt | Q57: 46345 | R57: In Progress
A58: CTRL-0019 | B58: Change Control 54 | C58: GOVERN | D58: GV.RR | E58: Human Resources | F58: Europe | G58: United Kingdom | H58: Critical | I58: Maya Patel | J58: Quarterly | K58: 45885 | L58: 45975 | M58: Overdue | N58: Missing | O58: 1 | P58: Maya Patel | Q58: 46250 | R58: Overdue
A59: CTRL-0020 | B59: Access Control 55 | C59: RECOVER | D59: RC.RP | E59: Risk & Compliance | F59: North America | G59: United States | H59: Medium | I59: Liam Brown | J59: Annual | K59: 46126 | L59: 46216 | M59: Overdue | N59: Complete | O59: 2 | P59: Sam Rivera | Q59: 46259 | R59: Overdue
A60: CTRL-0056 | B60: Data Control 56 | C60: PROTECT | D60: PR.AA | E60: Risk & Compliance | F60: Europe | G60: United Kingdom | H60: Low | I60: Sam Rivera | J60: Annual | K60: 45944 | L60: 46034 | M60: Overdue | N60: Pending | O60: 1 | P60: Taylor Morgan | Q60: 46151 | R60: Completed
A61: CTRL-0057 | B61: Incident Control 57 | C61: RESPOND | D61: RS.MA | E61: Risk & Compliance | F61: Europe | G61: United Kingdom | H61: Medium | I61: Emma Schmidt | J61: Semiannual | K61: 46136 | L61: 46501 | M61: Completed | N61: Pending | O61: 0 | P61: Taylor Morgan | Q61: 46135 | R61: Not Required
A62: CTRL-0058 | B62: Vendor Control 58 | C62: GOVERN | D62: GV.RR | E62: Technology | F62: North America | G62: United States | H62: Critical | I62: Alex Chen | J62: Annual | K62: 45884 | L62: 46249 | M62: Overdue | N62: Pending | O62: 4 | P62: Liam Brown | Q62: 46135 | R62: Overdue
A63: CTRL-0059 | B63: Vendor Control 59 | C63: DETECT | D63: DE.CM | E63: Human Resources | F63: Europe | G63: United Kingdom | H63: Medium | I63: Liam Brown | J63: Annual | K63: 46229 | L63: 46409 | M63: Completed | N63: Pending | O63: 2 | P63: Liam Brown | Q63: 46168 | R63: Overdue
A64: CTRL-0060 | B64: Incident Control 60 | C64: GOVERN | D64: GV.OC | E64: Human Resources | F64: Europe | G64: Germany | H64: Low | I64: Maya Patel | J64: Annual | K64: 46114 | L64: 46294 | M64: Overdue | N64: Pending | O64: 0 | P64: Liam Brown | Q64: 46321 | R64: Not Required
... A87: CTRL-0083 | B87: Change Control 83 | C87: GOVERN | D87: GV.OC | E87: Technology | F87: Asia Pacific | G87: Singapore | H87: Low | I87: Alex Chen | J87: Annual | K87: 46208 | L87: 46298 | M87: Completed | N87: Complete | O87: 2 | P87: Emma Schmidt | Q87: 46123 | R87: Completed
A88: CTRL-0084 | B88: Data Control 84 | C88: IDENTIFY | D88: ID.AM | E88: Commercial | F88: Asia Pacific | G88: Singapore | H88: Low | I88: Liam Brown | J88: Quarterly | K88: 45877 | L88: 46057 | M88: Overdue | O88: 0 | P88: Taylor Morgan | Q88: 46346 | R88: Not Required
A89: CTRL-0085 | B89: Data Control 85 | C89: DETECT | D89: DE.CM | E89: Finance | F89: Europe | G89: United Kingdom | H89: Critical | I89: Emma Schmidt | J89: Quarterly | K89: 46057 | L89: 46422 | M89: Completed | N89: Missing | O89: 3 | P89: Maya Patel | Q89: 46152 | R89: Overdue
A90: CTRL-0086 | B90: Policy Control 86 | C90: GOVERN | D90: GV.RM | E90: Human Resources | F90: North America | G90: Canada | H90: Medium | I90: Noah Williams | J90: Annual | K90: 46080 | L90: 46445 | M90: Completed | N90: Pending | O90: 3 | P90: Sam Rivera | Q90: 46165 | R90: Overdue
A91: CTRL-0087 | B91: Reconciliation Control 87 | C91: RESPOND | D91: RS.MA | E91: Technology | F91: Europe | G91: Germany | H91: Medium | I91: Liam Brown | J91: Annual | K91: 46071 | L91: 46251 | M91: Overdue | N91: Missing | O91: 0 | P91: Taylor Morgan | Q91: 46275 | R91: Not Required
A92: CTRL-0088 | B92: Data Control 88 | C92: GOVERN | D92: GV.OC | E92: Commercial | F92: Europe | G92: United Kingdom | H92: Critical | I92: Maya Patel | J92: Annual | K92: 46229 | L92: 46319 | M92: Completed | N92: Complete | O92: 5 | P92: Noah Williams | Q92: 46305 | R92: In Progress
A93: CTRL-0089 | B93: Change Control 89 | C93: IDENTIFY | D93: ID.AM | E93: Risk & Compliance | F93: Asia Pacific | G93: Singapore | H93: Medium | I93: Emma Schmidt | J93: Annual | K93: 45831 | L93: 46196 | M93: Overdue | N93: Complete | O93: 2 | P93: Liam Brown | Q93: 46274 | R93: Overdue
A94: CTRL-0090 | B94: Access Control 90 | C94: PROTECT | D94: PR.AA | E94: Operations | F94: North America | G94: United States | H94: High | I94: Noah Williams | J94: Quarterly | K94: 46217 | L94: 46397 | M94: Not Started | N94: Missing | O94: 4 | P94: Taylor Morgan | Q94: 46400 | R94: Completed
A95: CTRL-0091 | B95: Access Control 91 | C95: GOVERN | D95: GV.OC | E95: Operations | F95: Asia Pacific | G95: Singapore | H95: Medium | I95: Jordan Lee | J95: Annual | K95: 45830 | L95: 45920 | M95: Overdue | N95: Missing | O95: 3 | P95: Sam Rivera | Q95: 46150 | R95: Completed
A96: CTRL-0092 | B96: Change Control 92 | C96: GOVERN | D96: GV.RR | E96: Risk & Compliance | F96: Europe | G96: Germany | H96: Medium | I96: Noah Williams | J96: Annual | K96: 46116 | L96: 46481 | M96: Completed | N96: Missing | O96: 0 | P96: Alex Chen | Q96: 46141 | R96: Not Required
A97: CTRL-0093 | B97: Access Control 93 | C97: RESPOND | D97: RS.MA | E97: Operations | F97: Asia Pacific | G97: Singapore | H97: Medium | I97: Emma Schmidt | J97: Semiannual | K97: 46027 | L97: 46392 | M97: Completed | N97: Pending | O97: 1 | P97: Liam Brown | Q97: 46377 | R97: Completed
...

Sheet Data_Quality
A1: Data Quality & Exception Checks
A4: Control_ID | B4: Duplicate_Flag | C4: Missing_Owner | D4: Missing_Evidence | E4: Country_Issue | F4: BU_Whitespace | G4: Overdue_Review | H4: Overdue_Remediation | I4: Overall_Result
A5: =Controls_Raw!A5 -> CTRL-0001 | B5: =IF(COUNTIF(Controls_Raw!$A$5:$A$1504,A5)>1,"Duplicate","OK") -> Duplicate | C5: =IF(LEN(TRIM(Controls_Raw!I5))=0,"Missing","OK") -> Missing | D5: =IF(LEN(TRIM(Controls_Raw!N5))=0,"Missing","OK") -> Missing | E5: =IF(OR(Controls_Raw!G5="USA",Controls_Raw!G5="UK"),"Standardize","OK") -> OK | F5: =IF(Controls_Raw!E5<>TRIM(Controls_Raw!E5),"Trim","OK") -> Trim | G5: =IF(AND(Controls_Raw!L5<DATE(2026,9,30),Controls_Raw!M5<>"Completed"),"Overdue","OK") -> Overdue | H5: =IF(AND(Controls_Raw!Q5<DATE(2026,9,30),Controls_Raw!R5<>"Completed",Controls_Raw!R5<>"Not Required"),"Overdue","OK") -> Overdue | I5: =IF(COUNTIF(B5:H5,"<>OK")>0,"Issue","Pass") -> Issue
A6: =Controls_Raw!A6 -> CTRL-0002 | B6: =IF(COUNTIF(Controls_Raw!$A$5:$A$1504,A6)>1,"Duplicate","OK") -> Duplicate | C6: =IF(LEN(TRIM(Controls_Raw!I6))=0,"Missing","OK") -> OK | D6: =IF(LEN(TRIM(Controls_Raw!N6))=0,"Missing","OK") -> OK | E6: =IF(OR(Controls_Raw!G6="USA",Controls_Raw!G6="UK"),"Standardize","OK") -> OK | F6: =IF(Controls_Raw!E6<>TRIM(Controls_Raw!E6),"Trim","OK") -> OK | G6: =IF(AND(Controls_Raw!L6<DATE(2026,9,30),Controls_Raw!M6<>"Completed"),"Overdue","OK") -> Overdue | H6: =IF(AND(Controls_Raw!Q6<DATE(2026,9,30),Controls_Raw!R6<>"Completed",Controls_Raw!R6<>"Not Required"),"Overdue","OK") -> Overdue | I6: =IF(COUNTIF(B6:H6,"<>OK")>0,"Issue","Pass") -> Issue
A7: =Controls_Raw!A7 -> CTRL-0003 | B7: =IF(COUNTIF(Controls_Raw!$A$5:$A$1504,A7)>1,"Duplicate","OK") -> Duplicate | C7: =IF(LEN(TRIM(Controls_Raw!I7))=0,"Missing","OK") -> OK | D7: =IF(LEN(TRIM(Controls_Raw!N7))=0,"Missing","OK") -> OK | E7: =IF(OR(Controls_Raw!G7="USA",Controls_Raw!G7="UK"),"Standardize","OK") -> OK | F7: =IF(Controls_Raw!E7<>TRIM(Controls_Raw!E7),"Trim","OK") -> OK | G7: =IF(AND(Controls_Raw!L7<DATE(2026,9,30),Controls_Raw!M7<>"Completed"),"Overdue","OK") -> Overdue | H7: =IF(AND(Controls_Raw!Q7<DATE(2026,9,30),Controls_Raw!R7<>"Completed",Controls_Raw!R7<>"Not Required"),"Overdue","OK") -> OK | I7: =IF(COUNTIF(B7:H7,"<>OK")>0,"Issue","Pass") -> Issue
A8: =Controls_Raw!A8 -> CTRL-0004 | B8: =IF(COUNTIF(Controls_Raw!$A$5:$A$1504,A8)>1,"Duplicate","OK") -> Duplicate | C8: =IF(LEN(TRIM(Controls_Raw!I8))=0,"Missing","OK") -> OK | D8: =IF(LEN(TRIM(Controls_Raw!N8))=0,"Missing","OK") -> OK | E8: =IF(OR(Controls_Raw!G8="USA",Controls_Raw!G8="UK"),"Standardize","OK") -> OK | F8: =IF(Controls_Raw!E8<>TRIM(Controls_Raw!E8),"Trim","OK") -> OK | G8: =IF(AND(Controls_Raw!L8<DATE(2026,9,30),Controls_Raw!M8<>"Completed"),"Overdue","OK") -> OK | H8: =IF(AND(Controls_Raw!Q8<DATE(2026,9,30),Controls_Raw!R8<>"Completed",Controls_Raw!R8<>"Not Required"),"Overdue","OK") -> OK | I8: =IF(COUNTIF(B8:H8,"<>OK")>0,"Issue","Pass") -> Issue
A9: =Controls_Raw!A9 -> CTRL-0005 | B9: =IF(COUNTIF(Controls_Raw!$A$5:$A$1504,A9)>1,"Duplicate","OK") -> Duplicate | C9: =IF(LEN(TRIM(Controls_Raw!I9))=0,"Missing","OK") -> OK | D9: =IF(LEN(TRIM(Controls_Raw!N9))=0,"Missing","OK") -> OK | E9: =IF(OR(Controls_Raw!G9="USA",Controls_Raw!G9="UK"),"Standardize","OK") -> OK | F9: =IF(Controls_Raw!E9<>TRIM(Controls_Raw!E9),"Trim","OK") -> OK | G9: =IF(AND(Controls_Raw!L9<DATE(2026,9,30),Controls_Raw!M9<>"Completed"),"Overdue","OK") -> OK | H9: =IF(AND(Controls_Raw!Q9<DATE(2026,9,30),Controls_Raw!R9<>"Completed",Controls_Raw!R9<>"Not Required"),"Overdue","OK") -> OK | I9: =IF(COUNTIF(B9:H9,"<>OK")>0,"Issue","Pass") -> Issue
A10: =Controls_Raw!A10 -> CTRL-0006 | B10: =IF(COUNTIF(Controls_Raw!$A$5:$A$1504,A10)>1,"Duplicate","OK") -> Duplicate | C10: =IF(LEN(TRIM(Controls_Raw!I10))=0,"Missing","OK") -> OK | D10: =IF(LEN(TRIM(Controls_Raw!N10))=0,"Missing","OK") -> OK | E10: =IF(OR(Controls_Raw!G10="USA",Controls_Raw!G10="UK"),"Standardize","OK") -> OK | F10: =IF(Controls_Raw!E10<>TRIM(Controls_Raw!E10),"Trim","OK") -> OK | G10: =IF(AND(Controls_Raw!L10<DATE(2026,9,30),Controls_Raw!M10<>"Completed"),"Overdue","OK") -> Overdue | H10: =IF(AND(Controls_Raw!Q10<DATE(2026,9,30),Controls_Raw!R10<>"Completed",Controls_Raw!R10<>"Not Required"),"Overdue","OK") -> OK | I10: =IF(COUNTIF(B10:H10,"<>OK")>0,"Issue","Pass") -> Issue
A11: =Controls_Raw!A11 -> CTRL-0007 | B11: =IF(COUNTIF(Controls_Raw!$A$5:$A$1504,A11)>1,"Duplicate","OK") -> Duplicate | C11: =IF(LEN(TRIM(Controls_Raw!I11))=0,"Missing","OK") -> OK | D11: =IF(LEN(TRIM(Controls_Raw!N11))=0,"Missing","OK") -> OK | E11: =IF(OR(Controls_Raw!G11="USA",Controls_Raw!G11="UK"),"Standardize","OK") -> OK | F11: =IF(Controls_Raw!E11<>TRIM(Controls_Raw!E11),"Trim","OK") -> OK | G11: =IF(AND(Controls_Raw!L11<DATE(2026,9,30),Controls_Raw!M11<>"Completed"),"Overdue","OK") -> Overdue | H11: =IF(AND(Controls_Raw!Q11<DATE(2026,9,30),Controls_Raw!R11<>"Completed",Controls_Raw!R11<>"Not Required"),"Overdue","OK") -> Overdue | I11: =IF(COUNTIF(B11:H11,"<>OK")>0,"Issue","Pass") -> Issue
A12: =Controls_Raw!A12 -> CTRL-0008 | B12: =IF(COUNTIF(Controls_Raw!$A$5:$A$1504,A12)>1,"Duplicate","OK") -> Duplicate | C12: =IF(LEN(TRIM(Controls_Raw!I12))=0,"Missing","OK") -> OK | D12: =IF(LEN(TRIM(Controls_Raw!N12))=0,"Missing","OK") -> OK | E12: =IF(OR(Controls_Raw!G12="USA",Controls_Raw!G12="UK"),"Standardize","OK") -> OK | F12: =IF(Controls_Raw!E12<>TRIM(Controls_Raw!E12),"Trim","OK") -> OK | G12: =IF(AND(Controls_Raw!L12<DATE(2026,9,30),Controls_Raw!M12<>"Completed"),"Overdue","OK") -> Overdue | H12: =IF(AND(Controls_Raw!Q12<DATE(2026,9,30),Controls_Raw!R12<>"Completed",Controls_Raw!R12<>"Not Required"),"Overdue","OK") -> OK | I12: =IF(COUNTIF(B12:H12,"<>OK")>0,"Issue","Pass") -> Issue
A13: =Controls_Raw!A13 -> CTRL-0009 | B13: =IF(COUNTIF(Controls_Raw!$A$5:$A$1504,A13)>1,"Duplicate","OK") -> Duplicate | C13: =IF(LEN(TRIM(Controls_Raw!I13))=0,"Missing","OK") -> OK | D13: =IF(LEN(TRIM(Controls_Raw!N13))=0,"Missing","OK") -> OK | E13: =IF(OR(Controls_Raw!G13="USA",Controls_Raw!G13="UK"),"Standardize","OK") -> OK | F13: =IF(Controls_Raw!E13<>TRIM(Controls_Raw!E13),"Trim","OK") -> OK | G13: =IF(AND(Controls_Raw!L13<DATE(2026,9,30),Controls_Raw!M13<>"Completed"),"Overdue","OK") -> Overdue | H13: =IF(AND(Controls_Raw!Q13<DATE(2026,9,30),Controls_Raw!R13<>"Completed",Controls_Raw!R13<>"Not Required"),"Overdue","OK") -> OK | I13: =IF(COUNTIF(B13:H13,"<>OK")>0,"Issue","Pass") -> Issue
A14: =Controls_Raw!A14 -> CTRL-0010 | B14: =IF(COUNTIF(Controls_Raw!$A$5:$A$1504,A14)>1,"Duplicate","OK") -> Duplicate | C14: =IF(LEN(TRIM(Controls_Raw!I14))=0,"Missing","OK") -> OK | D14: =IF(LEN(TRIM(Controls_Raw!N14))=0,"Missing","OK") -> OK | E14: =IF(OR(Controls_Raw!G14="USA",Controls_Raw!G14="UK"),"Standardize","OK") -> OK | F14: =IF(Controls_Raw!E14<>TRIM(Controls_Raw!E14),"Trim","OK") -> OK | G14: =IF(AND(Controls_Raw!L14<DATE(2026,9,30),Controls_Raw!M14<>"Completed"),"Overdue","OK") -> Overdue | H14: =IF(AND(Controls_Raw!Q14<DATE(2026,9,30),Controls_Raw!R14<>"Completed",Controls_Raw!R14<>"Not Required"),"Overdue","OK") -> OK | I14: =IF(COUNTIF(B14:H14,"<>OK")>0,"Issue","Pass") -> Issue
A15: =Controls_Raw!A15 -> CTRL-0011 | B15: =IF(COUNTIF(Controls_Raw!$A$5:$A$1504,A15)>1,"Duplicate","OK") -> Duplicate | C15: =IF(LEN(TRIM(Controls_Raw!I15))=0,"Missing","OK") -> OK | D15: =IF(LEN(TRIM(Controls_Raw!N15))=0,"Missing","OK") -> OK | E15: =IF(OR(Controls_Raw!G15="USA",Controls_Raw!G15="UK"),"Standardize","OK") -> OK | F15: =IF(Controls_Raw!E15<>TRIM(Controls_Raw!E15),"Trim","OK") -> OK | G15: =IF(AND(Controls_Raw!L15<DATE(2026,9,30),Controls_Raw!M15<>"Completed"),"Overdue","OK") -> OK | H15: =IF(AND(Controls_Raw!Q15<DATE(2026,9,30),Controls_Raw!R15<>"Completed",Controls_Raw!R15<>"Not Required"),"Overdue","OK") -> OK | I15: =IF(COUNTIF(B15:H15,"<>OK")>0,"Issue","Pass") -> Issue
A16: =Controls_Raw!A16 -> CTRL-0012 | B16: =IF(COUNTIF(Controls_Raw!$A$5:$A$1504,A16)>1,"Duplicate","OK") -> Duplicate | C16: =IF(LEN(TRIM(Controls_Raw!I16))=0,"Missing","OK") -> OK | D16: =IF(LEN(TRIM(Controls_Raw!N16))=0,"Missing","OK") -> OK | E16: =IF(OR(Controls_Raw!G16="USA",Controls_Raw!G16="UK"),"Standardize","OK") -> OK | F16: =IF(Controls_Raw!E16<>TRIM(Controls_Raw!E16),"Trim","OK") -> OK | G16: =IF(AND(Controls_Raw!L16<DATE(2026,9,30),Controls_Raw!M16<>"Completed"),"Overdue","OK") -> Overdue | H16: =IF(AND(Controls_Raw!Q16<DATE(2026,9,30),Controls_Raw!R16<>"Completed",Controls_Raw!R16<>"Not Required"),"Overdue","OK") -> OK | I16: =IF(COUNTIF(B16:H16,"<>OK")>0,"Issue","Pass") -> Issue
... A1504: =Controls_Raw!A1504 -> CTRL-1500 | B1504: =IF(COUNTIF(Controls_Raw!$A$5:$A$1504,A1504)>1,"Duplicate","OK") -> OK | C1504: =IF(LEN(TRIM(Controls_Raw!I1504))=0,"Missing","OK") -> OK | D1504: =IF(LEN(TRIM(Controls_Raw!N1504))=0,"Missing","OK") -> OK | E1504: =IF(OR(Controls_Raw!G1504="USA",Controls_Raw!G1504="UK"),"Standardize","OK") -> OK | F1504: =IF(Controls_Raw!E1504<>TRIM(Controls_Raw!E1504),"Trim","OK") -> OK | G1504: =IF(AND(Controls_Raw!L1504<DATE(2026,9,30),Controls_Raw!M1504<>"Completed"),"Overdue","OK") -> OK | H1504: =IF(AND(Controls_Raw!Q1504<DATE(2026,9,30),Controls_Raw!R1504<>"Completed",Controls_Raw!R1504<>"Not Required"),"Overdue","OK") -> OK | I1504: =IF(COUNTIF(B1504:H1504,"<>OK")>0,"Issue","Pass") -> Pass

Sheet Dashboard
A1: Governance & Compliance Dashboard
A4: Total Controls | D4: High/Critical | G4: Overdue Reviews | J4: Missing Owners
A5: 1500 | D5: 443 | G5: 878 | J5: 32
A9: Region | B9: Controls
A10: Asia Pacific | B10: 485
A11: North America | B11: 478
A12: Europe | B12: 537

Sheet Power_Query_Steps
A1: Power Query Build Steps
A4: Step | B4: Action | C4: Instruction
A5: 1 | B5: Open source | C5: Controls_Raw → click inside table → Data → From Table/Range.
A6: 2 | B6: Set types | C6: Set date fields to Date, Issue_Count to Whole Number, identifiers/text to Text.
A7: 3 | B7: Trim/Clean | C7: Transform → Format → Trim/Clean on business unit, country, owner, evidence fields.
A8: 4 | B8: Standardize | C8: Replace USA with United States and UK with United Kingdom.
A9: 5 | B9: Inspect duplicates | C9: Select Control_ID → Keep Duplicates for review; do not delete blindly.
A10: 6 | B10: Preserve exceptions | C10: Do not invent missing owners/evidence; keep them visible for governance follow-up.
A11: 7 | B11: Load | C11: Close & Load to a new table and compare with Cleaned_Controls.
A12: 8 | B12: Refresh test | C12: Change a raw record and Data → Refresh All.

Sheet PowerBI_Measures
A1: Power BI Starter Measures
A4: Measure | B4: DAX | C4: Use
A5: Total Controls | B5: Total Controls = COUNTROWS(Controls) | C5: Executive reporting
A6: Completed Controls | B6: Completed Controls = CALCULATE([Total Controls], Controls[Status] = "Completed") | C6: Executive reporting
A7: Completion Rate | B7: Completion Rate = DIVIDE([Completed Controls],[Total Controls],0) | C7: Executive reporting
A8: High Critical Controls | B8: High Critical Controls = CALCULATE([Total Controls], Controls[Risk_Level] IN {"High","Critical"}) | C8: Executive reporting
A9: Total Issues | B9: Total Issues = SUM(Controls[Issue_Count]) | C9: Executive reporting

Sheet Sources
A1: Sources & Data Provenance
A4: Source | B4: How Used | C4: URL | D4: Authority
A5: NIST Cybersecurity Framework 2.0 | B5: Taxonomy/reference basis | C5: https://nvlpubs.nist.gov/nistpubs/CSWP/NIST.CSWP.29.pdf | D5: Official NIST
A6: ISO 3166 Country Codes | B6: Country standardization reference | C6: https://www.iso.org/iso-3166-country-codes.html | D6: Official ISO
A7: Microsoft Power BI SharePoint List | B7: Implementation guidance | C7: https://learn.microsoft.com/en-us/power-bi/connect-data/desktop-sharepoint-online-list | D7: Microsoft Learn
A8: Power Automate Approvals | B8: Approval workflow guidance | C8: https://learn.microsoft.com/en-us/power-automate/modern-approvals | D8: Microsoft Learn
